Workbook

Sheet Start Here
B4: MAIA
B5: Financial Model — Scarlot Coverage Pack
B6: v1.0 — April 2026
B10: HOW TO USE THIS MODEL
B12: 1. START WITH ASSUMPTIONS — The Assumptions sheet is the control panel. Every yellow cell is an input you can change. All other sheets are formula-driven — do not edit them directly.
B14: 2. SCENARIO TOGGLE — Cell B2 on Assumptions controls the scenario: 1=Conservative, 2=Base, 3=Optimistic. The entire model recalculates when you switch.
B16: 3. MONTHLY VECTORS — Many inputs (salaries, tier mix, churn) can be set month-by-month in columns C–AL. This lets you model ramp-ups and seasonal changes.
B18: 4. SCENARIO COMPARISON — The Scenarios sheet compares all three. Set toggle to 1, copy values to column B. Set to 2, leave as formulas. Set to 3, copy to column D.
B20: 5. KEY OUTPUTS — P&L shows profitability. Cash Flow shows runway. Unit Economics shows LTV/CAC (>3 is healthy). Scenarios shows the range.
B24: SHEET GUIDE
B26: Sheet | C26: Purpose | D26: Type | E26: Key Metric
B27: Start Here | C27: You are here | D27: GUIDE | E27: —
B28: Assumptions | C28: All editable inputs | D28: INPUT | E28: —
B29: Revenue | C29: User growth, tiers, revenue | D29: CALCULATED | E29: MRR, ARR
B30: Costs | C30: Fixed + variable + one-time | D30: CALCULATED | E30: Monthly burn
B31: Unit Economics | C31: Per-user profitability | D31: DERIVED | E31: LTV/CAC
B32: P&L | C32: Profit & Loss | D32: DERIVED | E32: Net Income
B33: Cash Flow | C33: Cash position & runway | D33: DERIVED | E33: Runway months
B34: Scenarios | C34: Side-by-side comparison | D34: SUMMARY | E34: Breakeven
B35: Pricing | C35: What’s in each tier | D35: REFERENCE | E35: —
B39: KEY ASSUMPTIONS TO REVIEW
B41: Assumption | C41: Default | D41: Cell | E41: Why It Matters
B42: Round 1 Raise | C42: CHF 120,000 | D42: Assumptions B5 | E42: Determines runway. Current model shows ~CHF 36K cash gap at Y1.
B43: WOM Referral Rate | C43: 30% | D43: Assumptions B18 | E43: Key growth driver. Compounds monthly from M4.
B44: Referral Conversion | C44: 0.3 | D44: Assumptions B19 | E44: % of referrals who sign up. Tight community = high conversion.
B45: Outreach Capture Rate | C45: 0.05 | D45: Assumptions B21 | E45: Automated AI-generated outreach. 5% = 1 in 20 contacted sign up.
B46: Monthly Churn | C46: 10% → 7% → 5% | D46: Assumptions R35 | E46: Ramps down: 10% M1-6, 7% M7-12, 5% M13+. Summer bump +2%.
B47: Co-founder 1 Salary | C47: CHF 5,500/mo from M1 | D47: Assumptions R56 | E47: Biggest early fixed cost.
B48: CTO Salary | C48: CHF 1,800/mo from M7 | D48: Assumptions R58 | E48: 20% of full-time rate.
B49: International Launch | C49: Month 6 (Nov 2026) | D49: Assumptions B25 | E49: When WOM spills beyond Switzerland. 2x multiplier.
B50: Pro+ Price | C50: CHF 69/mo | D50: Assumptions B13 | E50: Power user tier. Raised from CHF 55.
B51: Market Ceiling FR-CH | C51: 1500 | D51: Assumptions B23 | E51: Growth cap for Swiss market. International unlocks at M6.
B54: NOTES
B56: • All amounts in CHF. AI costs converted from USD at Assumptions B50.
B57: • Model starts June 2026. Calendar months shown in headers.
B58: • Base case breaks even at month 14 (Aug 2027). Cash gap of ~CHF 36K at Y1 requires raise above CHF 120K or cost cuts.
B59: • International expansion at month 6 is critical — FR-CH ceiling (1,500) is hit before Y2 without it.
B60: • WOM (30% × 30% = 9% effective monthly growth) is the primary growth engine after M4. If this doesn't materialize, the model fails.
B61: • Conservative scenario (toggle = 1) shows the downside with 0.5x growth and 2x churn.

Sheet Assumptions
A1: Section | B1: Value/Units | C1: Jun 2026 | D1: Jul 2026 | E1: Aug 2026 | F1: Sep 2026 | G1: Oct 2026 | H1: Nov 2026 | I1: Dec 2026 | J1: Jan 2027 | K1: Feb 2027 | L1: Mar 2027 | M1: Apr 2027 | N1: May 2027 | O1: Jun 2027 | P1: Jul 2027 | Q1: Aug 2027 | R1: Sep 2027 | S1: Oct 2027 | T1: Nov 2027 | U1: Dec 2027 | V1: Jan 2028 | W1: Feb 2028 | X1: Mar 2028 | Y1: Apr 2028 | Z1: May 2028 | AA1: Jun 2028 | AB1: Jul 2028 | AC1: Aug 2028 | AD1: Sep 2028 | AE1: Oct 2028 | AF1: Nov 2028 | AG1: Dec 2028 | AH1: Jan 2029 | AI1: Feb 2029 | AJ1: Mar 2029 | AK1: Apr 2029 | AL1: May 2029
A2: Scenario Toggle | B2: 2
A3: Entity Type | B3: SA
A4: ROUND 1
A5: Round 1 Raise Amount | B5: 120000
A6: Company Formation Fees | B6: 7000
A7: Company Share Capital | B7: 50000
A8: Net Starting Cash | B8: =B5-B6 -> 113000
A9: PRICING
A10: Free Tier Price | B10: 0
A11: Solo Tier Price (CHF/mo) | B11: 15
A12: Pro Tier Price (CHF/mo) | B12: 35
A13: Pro+ Tier Price (CHF/mo) | B13: 69
A14: Add-on Price (CHF/mo) | B14: 0
A15: USER ACQUISITION
A16: Beta New Users | B16: users/mo | C16: 3 | D16: 7 | E16: 12 | F16: 20 | G16: 0 | H16: 0 | I16: 0 | J16: 0 | K16: 0 | L16: 0 | M16: 0 | N16: 0 | O16: 0 | P16: 0 | Q16: 0 | R16: 0 | S16: 0 | T16: 0 | U16: 0 | V16: 0 | W16: 0 | X16: 0 | Y16: 0 | Z16: 0 | AA16: 0 | AB16: 0 | AC16: 0 | AD16: 0 | AE16: 0 | AF16: 0 | AG16: 0 | AH16: 0 | AI16: 0 | AJ16: 0 | AK16: 0 | AL16: 0
A17: Partner New Users (Aspasie etc) | B17: users/mo | C17: 0 | D17: 0 | E17: 0 | F17: 0 | G17: 0 | H17: 0 | I17: 0 | J17: 0 | K17: 0 | L17: 0 | M17: 0 | N17: 0 | O17: 0 | P17: 0 | Q17: 0 | R17: 0 | S17: 0 | T17: 0 | U17: 0 | V17: 0 | W17: 0 | X17: 0 | Y17: 0 | Z17: 0 | AA17: 0 | AB17: 0 | AC17: 0 | AD17: 0 | AE17: 0 | AF17: 0 | AG17: 0 | AH17: 0 | AI17: 0 | AJ17: 0 | AK17: 0 | AL17: 0
A18: WOM Referral Rate | B18: 0.3
A19: Referral Conversion Rate | B19: 0.3
A20: Direct Outreach Messages/mo | B20: msgs/mo | C20: 100 | D20: 100 | E20: 100 | F20: 300 | G20: 300 | H20: 300 | I20: 500 | J20: 500 | K20: 500 | L20: 500 | M20: 500 | N20: 500 | O20: 700 | P20: 700 | Q20: 700 | R20: 700 | S20: 700 | T20: 700 | U20: 700 | V20: 700 | W20: 700 | X20: 700 | Y20: 700 | Z20: 700 | AA20: 1000 | AB20: 1000 | AC20: 1000 | AD20: 1000 | AE20: 1000 | AF20: 1000 | AG20: 1000 | AH20: 1000 | AI20: 1000 | AJ20: 1000 | AK20: 1000 | AL20: 1000
A21: Outreach Capture Rate | B21: 0.05
A22: Seasonality Factor | B22: multiplier | C22: 1 | D22: 1 | E22: 1 | F22: 1 | G22: 1 | H22: 0.85 | I22: 0.7 | J22: 0.75 | K22: 1 | L22: 1 | M22: 1 | N22: 0.9 | O22: 1 | P22: 1 | Q22: 1 | R22: 1 | S22: 1 | T22: 0.85 | U22: 0.7 | V22: 0.75 | W22: 1 | X22: 1 | Y22: 1 | Z22: 0.9 | AA22: 1 | AB22: 1 | AC22: 1 | AD22: 1 | AE22: 1 | AF22: 0.85 | AG22: 0.7 | AH22: 0.75 | AI22: 1 | AJ22: 1 | AK22: 1 | AL22: 0.9
A23: Market Ceiling (FR-CH) | B23: 1500
A24: Market Ceiling (all CH) | B24: 7221
A25: International Launch Month | B25: 6
A26: International Market Size | B26: 50000
A27: Cross-border WOM Multiplier | B27: 1.5
A28: TIER MIX
A29: % Free | B29: % | C29: 0.85 | D29: 0.85 | E29: 0.85 | F29: 0.15 | G29: 0.15 | H29: 0.15 | I29: 0.15 | J29: 0.15 | K29: 0.15 | L29: 0.15 | M29: 0.15 | N29: 0.15 | O29: 0.05 | P29: 0.05 | Q29: 0.05 | R29: 0.05 | S29: 0.05 | T29: 0.05 | U29: 0.05 | V29: 0.05 | W29: 0.05 | X29: 0.05 | Y29: 0.05 | Z29: 0.05 | AA29: 0.05 | AB29: 0.05 | AC29: 0.05 | AD29: 0.05 | AE29: 0.05 | AF29: 0.05 | AG29: 0.05 | AH29: 0.05 | AI29: 0.05 | AJ29: 0.05 | AK29: 0.05 | AL29: 0.05
A30: % Solo | B30: % | C30: 0.05 | D30: 0.05 | E30: 0.05 | F30: 0.25 | G30: 0.25 | H30: 0.25 | I30: 0.25 | J30: 0.25 | K30: 0.25 | L30: 0.25 | M30: 0.25 | N30: 0.25 | O30: 0.25 | P30: 0.25 | Q30: 0.25 | R30: 0.25 | S30: 0.25 | T30: 0.25 | U30: 0.25 | V30: 0.25 | W30: 0.25 | X30: 0.25 | Y30: 0.25 | Z30: 0.25 | AA30: 0.25 | AB30: 0.25 | AC30: 0.25 | AD30: 0.25 | AE30: 0.25 | AF30: 0.25 | AG30: 0.25 | AH30: 0.25 | AI30: 0.25 | AJ30: 0.25 | AK30: 0.25 | AL30: 0.25
A31: % Pro | B31: % | C31: 0.05 | D31: 0.05 | E31: 0.05 | F31: 0.4 | G31: 0.4 | H31: 0.4 | I31: 0.4 | J31: 0.4 | K31: 0.4 | L31: 0.4 | M31: 0.4 | N31: 0.4 | O31: 0.45 | P31: 0.45 | Q31: 0.45 | R31: 0.45 | S31: 0.45 | T31: 0.45 | U31: 0.45 | V31: 0.45 | W31: 0.45 | X31: 0.45 | Y31: 0.45 | Z31: 0.45 | AA31: 0.45 | AB31: 0.45 | AC31: 0.45 | AD31: 0.45 | AE31: 0.45 | AF31: 0.45 | AG31: 0.45 | AH31: 0.45 | AI31: 0.45 | AJ31: 0.45 | AK31: 0.45 | AL31: 0.45
A32: % Pro+ | B32: % | C32: 0.05 | D32: 0.05 | E32: 0.05 | F32: 0.2 | G32: 0.2 | H32: 0.2 | I32: 0.2 | J32: 0.2 | K32: 0.2 | L32: 0.2 | M32: 0.2 | N32: 0.2 | O32: 0.25 | P32: 0.25 | Q32: 0.25 | R32: 0.25 | S32: 0.25 | T32: 0.25 | U32: 0.25 | V32: 0.25 | W32: 0.25 | X32: 0.25 | Y32: 0.25 | Z32: 0.25 | AA32: 0.25 | AB32: 0.25 | AC32: 0.25 | AD32: 0.25 | AE32: 0.25 | AF32: 0.25 | AG32: 0.25 | AH32: 0.25 | AI32: 0.25 | AJ32: 0.25 | AK32: 0.25 | AL32: 0.25
A33: Tier Mix Check | B33: must=100% | C33: =C29+C30+C31+C32 -> 1 | D33: =D29+D30+D31+D32 -> 1 | E33: =E29+E30+E31+E32 -> 1 | F33: =F29+F30+F31+F32 -> 1 | G33: =G29+G30+G31+G32 -> 1 | H33: =H29+H30+H31+H32 -> 1 | I33: =I29+I30+I31+I32 -> 1 | J33: =J29+J30+J31+J32 -> 1 | ... AL33: =AL29+AL30+AL31+AL32 -> 1
A34: CHURN & DEDUCTIONS
A35: Monthly Churn Rate | B35: % | C35: 0.1 | D35: 0.12 | E35: 0.12 | F35: 0.1 | G35: 0.1 | H35: 0.1 | I35: 0.07 | J35: 0.07 | K35: 0.07 | L35: 0.07 | M35: 0.07 | N35: 0.07 | O35: 0.05 | P35: 0.07 | Q35: 0.07 | R35: 0.05 | S35: 0.05 | T35: 0.05 | U35: 0.05 | V35: 0.05 | W35: 0.05 | X35: 0.05 | Y35: 0.05 | Z35: 0.05 | AA35: 0.05 | AB35: 0.07 | AC35: 0.07 | AD35: 0.05 | AE35: 0.05 | AF35: 0.05 | AG35: 0.05 | AH35: 0.05 | AI35: 0.05 | AJ35: 0.05 | AK35: 0.05 | AL35: 0.05
A36: Failed Payments Rate | B36: 0.03
A37: Payment Processing % | B37: 0.029
A38: Payment Processing Fixed (CHF) | B38: 0.3
A39: AI COSTS
A40: Messages per User per Month | B40: 150
...

Sheet Revenue
A1: Revenue Model | B1: Units | C1: Jun 2026 | D1: Jul 2026 | E1: Aug 2026 | F1: Sep 2026 | G1: Oct 2026 | H1: Nov 2026 | I1: Dec 2026 | J1: Jan 2027 | K1: Feb 2027 | L1: Mar 2027 | M1: Apr 2027 | N1: May 2027 | O1: Jun 2027 | P1: Jul 2027 | Q1: Aug 2027 | R1: Sep 2027 | S1: Oct 2027 | T1: Nov 2027 | U1: Dec 2027 | V1: Jan 2028 | W1: Feb 2028 | X1: Mar 2028 | Y1: Apr 2028 | Z1: May 2028 | AA1: Jun 2028 | AB1: Jul 2028 | AC1: Aug 2028 | AD1: Sep 2028 | AE1: Oct 2028 | AF1: Nov 2028 | AG1: Dec 2028 | AH1: Jan 2029 | AI1: Feb 2029 | AJ1: Mar 2029 | AK1: Apr 2029 | AL1: May 2029
A2: USER ACQUISITION
A3: Beta New Users | C3: =Assumptions!C16 -> 3 | D3: =Assumptions!D16 -> 7 | E3: =Assumptions!E16 -> 12 | F3: =Assumptions!F16 -> 20 | G3: =Assumptions!G16 -> 0 | H3: =Assumptions!H16 -> 0 | I3: =Assumptions!I16 -> 0 | J3: =Assumptions!J16 -> 0 | ... AL3: =Assumptions!AL16 -> 0
A4: Partner New Users | C4: =Assumptions!C17 -> 0 | D4: =Assumptions!D17 -> 0 | E4: =Assumptions!E17 -> 0 | F4: =Assumptions!F17 -> 0 | G4: =Assumptions!G17 -> 0 | H4: =Assumptions!H17 -> 0 | I4: =Assumptions!I17 -> 0 | J4: =Assumptions!J17 -> 0 | ... AL4: =Assumptions!AL17 -> 0
A5: Outreach New Users | C5: =Assumptions!C20*Assumptions!$B$21 -> 5 | D5: =Assumptions!D20*Assumptions!$B$21 -> 5 | E5: =Assumptions!E20*Assumptions!$B$21 -> 5 | F5: =Assumptions!F20*Assumptions!$B$21 -> 15 | G5: =Assumptions!G20*Assumptions!$B$21 -> 15 | H5: =Assumptions!H20*Assumptions!$B$21 -> 15 | I5: =Assumptions!I20*Assumptions!$B$21 -> 25 | J5: =Assumptions!J20*Assumptions!$B$21 -> 25 | ... AL5: =Assumptions!AL20*Assumptions!$B$21 -> 50
A6: WOM New Users | C6: 0 | D6: 0 | E6: 0 | F6: =E30*Assumptions!$B$18*Assumptions!$B$19*CHOOSE(Assumptions!$B$2,Assumptions!$B$88,Assumptions!$B$89,Assumptions!$B$90) -> 0.50024025 | G6: =F30*Assumptions!$B$18*Assumptions!$B$19*CHOOSE(Assumptions!$B$2,Assumptions!$B$88,Assumptions!$B$89,Assumptions!$B$90) -> 5.5627943 | H6: =G30*Assumptions!$B$18*Assumptions!$B$19*CHOOSE(Assumptions!$B$2,Assumptions!$B$88,Assumptions!$B$89,Assumptions!$B$90) -> 7.354423 | I6: =H30*Assumptions!$B$18*Assumptions!$B$19*CHOOSE(Assumptions!$B$2,Assumptions!$B$88,Assumptions!$B$89,Assumptions!$B$90) -> 8.9773835 | J6: =I30*Assumptions!$B$18*Assumptions!$B$19*CHOOSE(Assumptions!$B$2,Assumptions!$B$88,Assumptions!$B$89,Assumptions!$B$90) -> 11.339905 | K6: =J30*Assumptions!$B$18*Assumptions!$B$19*CHOOSE(Assumptions!$B$2,Assumptions!$B$88,Assumptions!$B$89,Assumptions!$B$90) -> 14.063736 | L6: =K30*Assumptions!$B$18*Assumptions!$B$19*CHOOSE(Assumptions!$B$2,Assumptions!$B$88,Assumptions!$B$89,Assumptions!$B$90) -> 17.768077 | M6: =L30*Assumptions!$B$18*Assumptions!$B$19*CHOOSE(Assumptions!$B$2,Assumptions!$B$88,Assumptions!$B$89,Assumptions!$B$90) -> 22.035894 | ... AL6: =AK30*Assumptions!$B$18*Assumptions!$B$19*CHOOSE(Assumptions!$B$2,Assumptions!$B$88,Assumptions!$B$89,Assumptions!$B$90) -> 429.3844
A7: Gross New Users | C7: =C3+C4+C5+C6 -> 8 | D7: =D3+D4+D5+D6 -> 12 | E7: =E3+E4+E5+E6 -> 17 | F7: =F3+F4+F5+F6 -> 35.50024 | G7: =G3+G4+G5+G6 -> 20.562794 | H7: =H3+H4+H5+H6 -> 22.354423 | I7: =I3+I4+I5+I6 -> 33.977383 | J7: =J3+J4+J5+J6 -> 36.339905 | ... AL7: =AL3+AL4+AL5+AL6 -> 479.3844
A8: Seasonality Factor | C8: =Assumptions!C22 -> 1 | D8: =Assumptions!D22 -> 1 | E8: =Assumptions!E22 -> 1 | F8: =Assumptions!F22 -> 1 | G8: =Assumptions!G22 -> 1 | H8: =Assumptions!H22 -> 0.85 | I8: =Assumptions!I22 -> 0.7 | J8: =Assumptions!J22 -> 0.75 | ... AL8: =Assumptions!AL22 -> 0.9
A9: Adjusted New Users | C9: =C7*C8 -> 8 | D9: =D7*D8 -> 12 | E9: =E7*E8 -> 17 | F9: =F7*F8 -> 35.50024 | G9: =G7*G8 -> 20.562794 | H9: =H7*H8 -> 19.00126 | I9: =I7*I8 -> 23.784168 | J9: =J7*J8 -> 27.254929 | ... AL9: =AL7*AL8 -> 431.44596
A10: Market Ceiling | B10: =Assumptions!$B$23 -> 1500 | C10: =Assumptions!$B$23 -> 1500 | D10: =Assumptions!$B$23 -> 1500 | E10: =Assumptions!$B$23 -> 1500 | F10: =Assumptions!$B$23 -> 1500 | G10: =Assumptions!$B$23 -> 1500 | H10: =Assumptions!$B$23 -> 1500 | I10: =Assumptions!$B$23 -> 1500 | ... AL10: =Assumptions!$B$23 -> 1500
A11: Prior Total Users | C11: 0 | D11: =C23 -> 8 | E11: =D23 -> 20.135 | F11: =E23 -> 37.558225 | G11: =F23 -> 72.808826 | H11: =G23 -> 95.715811 | I11: =H23 -> 117.74871 | J11: =I23 -> 147.99895 | K11: =J23 -> 183.26374 | ... AL11: =AK23 -> 5021.9377
A12: Headroom | C12: =C10-C11 -> 1500 | D12: =D10-D11 -> 1492 | E12: =E10-E11 -> 1479.865 | F12: =F10-F11 -> 1462.4418 | G12: =G10-G11 -> 1427.1912 | H12: =H10-H11 -> 1404.2842 | I12: =I10-I11 -> 1382.2513 | J12: =J10-J11 -> 1352.0011 | ... AL12: =AL10-AL11 -> -3521.9377
A13: Capped New Users | C13: =MIN(C9,MAX(C12,0)) -> 8 | D13: =MIN(D9,MAX(D12,0)) -> 12 | E13: =MIN(E9,MAX(E12,0)) -> 17 | F13: =MIN(F9,MAX(F12,0)) -> 35.50024 | G13: =MIN(G9,MAX(G12,0)) -> 20.562794 | H13: =MIN(H9,MAX(H12,0)) -> 19.00126 | I13: =MIN(I9,MAX(I12,0)) -> 23.784168 | J13: =MIN(J9,MAX(J12,0)) -> 27.254929 | ... AL13: =MIN(AL9,MAX(AL12,0)) -> 0
A14: International WOM Users | B14: users/mo | C14: 0 | D14: =IF(D1>=Assumptions!$B$25,C30*Assumptions!$B$18*Assumptions!$B$19*Assumptions!$B$27*CHOOSE(Assumptions!$B$2,Assumptions!$B$88,Assumptions!$B$89,Assumptions!$B$90),0) -> 0.135 | E14: =IF(E1>=Assumptions!$B$25,D30*Assumptions!$B$18*Assumptions!$B$19*Assumptions!$B$27*CHOOSE(Assumptions!$B$2,Assumptions!$B$88,Assumptions!$B$89,Assumptions!$B$90),0) -> 0.423225 | F14: =IF(F1>=Assumptions!$B$25,E30*Assumptions!$B$18*Assumptions!$B$19*Assumptions!$B$27*CHOOSE(Assumptions!$B$2,Assumptions!$B$88,Assumptions!$B$89,Assumptions!$B$90),0) -> 0.75036037 | G14: =IF(G1>=Assumptions!$B$25,F30*Assumptions!$B$18*Assumptions!$B$19*Assumptions!$B$27*CHOOSE(Assumptions!$B$2,Assumptions!$B$88,Assumptions!$B$89,Assumptions!$B$90),0) -> 8.3441915 | H14: =IF(H1>=Assumptions!$B$25,G30*Assumptions!$B$18*Assumptions!$B$19*Assumptions!$B$27*CHOOSE(Assumptions!$B$2,Assumptions!$B$88,Assumptions!$B$89,Assumptions!$B$90),0) -> 11.031635 | I14: =IF(I1>=Assumptions!$B$25,H30*Assumptions!$B$18*Assumptions!$B$19*Assumptions!$B$27*CHOOSE(Assumptions!$B$2,Assumptions!$B$88,Assumptions!$B$89,Assumptions!$B$90),0) -> 13.466075 | J14: =IF(J1>=Assumptions!$B$25,I30*Assumptions!$B$18*Assumptions!$B$19*Assumptions!$B$27*CHOOSE(Assumptions!$B$2,Assumptions!$B$88,Assumptions!$B$89,Assumptions!$B$90),0) -> 17.009858 | K14: =IF(K1>=Assumptions!$B$25,J30*Assumptions!$B$18*Assumptions!$B$19*Assumptions!$B$27*CHOOSE(Assumptions!$B$2,Assumptions!$B$88,Assumptions!$B$89,Assumptions!$B$90),0) -> 21.095604 | ... AL14: =IF(AL1>=Assumptions!$B$25,AK30*Assumptions!$B$18*Assumptions!$B$19*Assumptions!$B$27*CHOOSE(Assumptions!$B$2,Assumptions!$B$88,Assumptions!$B$89,Assumptions!$B$90),0) -> 644.0766
A15: International Ceiling | C15: =Assumptions!$B$26 -> 50000 | D15: =Assumptions!$B$26 -> 50000 | E15: =Assumptions!$B$26 -> 50000 | F15: =Assumptions!$B$26 -> 50000 | G15: =Assumptions!$B$26 -> 50000 | H15: =Assumptions!$B$26 -> 50000 | I15: =Assumptions!$B$26 -> 50000 | J15: =Assumptions!$B$26 -> 50000 | ... AL15: =Assumptions!$B$26 -> 50000
A16: Cumulative Intl Users | C16: 0 | D16: =MIN(C16+D14,D15) -> 0.135 | E16: =MIN(D16+E14,E15) -> 0.558225 | F16: =MIN(E16+F14,F15) -> 1.3085854 | G16: =MIN(F16+G14,G15) -> 9.6527768 | H16: =MIN(G16+H14,H15) -> 20.684411 | I16: =MIN(H16+I14,I15) -> 34.150487 | J16: =MIN(I16+J14,J15) -> 51.160345 | K16: =MIN(J16+K14,K15) -> 72.255949 | ... AL16: =MIN(AK16+AL14,AL15) -> 7269.0087
A17: Total New Users (CH + Intl) | C17: =C13+C16 -> 8 | D17: =D13+(D16-C16) -> 12.135 | E17: =E13+(E16-D16) -> 17.423225 | F17: =F13+(F16-E16) -> 36.250601 | G17: =G13+(G16-F16) -> 28.906986 | H17: =H13+(H16-G16) -> 30.032894 | I17: =I13+(I16-H16) -> 37.250244 | J17: =J13+(J16-I16) -> 44.264787 | K17: =K13+(K16-J16) -> 60.159341 | ... AL17: =AL13+(AL16-AK16) -> 644.0766
A18: CHURN
A19: Churn Rate (effective) | C19: =Assumptions!C35*CHOOSE(Assumptions!$B$2,Assumptions!$B$91,Assumptions!$B$92,Assumptions!$B$93) -> 0.1 | D19: =Assumptions!D35*CHOOSE(Assumptions!$B$2,Assumptions!$B$91,Assumptions!$B$92,Assumptions!$B$93) -> 0.12 | E19: =Assumptions!E35*CHOOSE(Assumptions!$B$2,Assumptions!$B$91,Assumptions!$B$92,Assumptions!$B$93) -> 0.12 | F19: =Assumptions!F35*CHOOSE(Assumptions!$B$2,Assumptions!$B$91,Assumptions!$B$92,Assumptions!$B$93) -> 0.1 | G19: =Assumptions!G35*CHOOSE(Assumptions!$B$2,Assumptions!$B$91,Assumptions!$B$92,Assumptions!$B$93) -> 0.1 | H19: =Assumptions!H35*CHOOSE(Assumptions!$B$2,Assumptions!$B$91,Assumptions!$B$92,Assumptions!$B$93) -> 0.1 | I19: =Assumptions!I35*CHOOSE(Assumptions!$B$2,Assumptions!$B$91,Assumptions!$B$92,Assumptions!$B$93) -> 0.07 | J19: =Assumptions!J35*CHOOSE(Assumptions!$B$2,Assumptions!$B$91,Assumptions!$B$92,Assumptions!$B$93) -> 0.07 | ... AL19: =Assumptions!AL35*CHOOSE(Assumptions!$B$2,Assumptions!$B$91,Assumptions!$B$92,Assumptions!$B$93) -> 0.05
A20: Churned Users | C20: 0 | D20: =ROUND(C30*D19,0) -> 0 | E20: =ROUND(D30*E19,0) -> 0 | F20: =ROUND(E30*F19,0) -> 1 | G20: =ROUND(F30*G19,0) -> 6 | H20: =ROUND(G30*H19,0) -> 8 | I20: =ROUND(H30*I19,0) -> 7 | J20: =ROUND(I30*J19,0) -> 9 | K20: =ROUND(J30*K19,0) -> 11 | ... AL20: =ROUND(AK30*AL19,0) -> 239
A21: USER TOTALS
A22: Start of Month Users | C22: 0 | D22: =C23 -> 8 | E22: =D23 -> 20.135 | F22: =E23 -> 37.558225 | G22: =F23 -> 72.808826 | H22: =G23 -> 95.715811 | I22: =H23 -> 117.74871 | J22: =I23 -> 147.99895 | K22: =J23 -> 183.26374 | ... AL22: =AK23 -> 5021.9377
A23: End of Month Users | C23: =C22+C17-C20 -> 8 | D23: =D22+D17-D20 -> 20.135 | E23: =E22+E17-E20 -> 37.558225 | F23: =F22+F17-F20 -> 72.808826 | G23: =G22+G17-G20 -> 95.715811 | H23: =H22+H17-H20 -> 117.74871 | I23: =I22+I17-I20 -> 147.99895 | J23: =J22+J17-J20 -> 183.26374 | ... AL23: =AL22+AL17-AL20 -> 5427.0143
A24: Net Change | C24: =C23-C22 -> 8 | D24: =D23-D22 -> 12.135 | E24: =E23-E22 -> 17.423225 | F24: =F23-F22 -> 35.250601 | G24: =G23-G22 -> 22.906986 | H24: =H23-H22 -> 22.032894 | I24: =I23-I22 -> 30.250244 | J24: =J23-J22 -> 35.264787 | ... AL24: =AL23-AL22 -> 405.0766
A25: TIER BREAKDOWN
A26: Free Users | C26: =ROUND(C23*Assumptions!C29,0) -> 7 | D26: =ROUND(D23*Assumptions!D29,0) -> 17 | E26: =ROUND(E23*Assumptions!E29,0) -> 32 | F26: =ROUND(F23*Assumptions!F29,0) -> 11 | G26: =ROUND(G23*Assumptions!G29,0) -> 14 | H26: =ROUND(H23*Assumptions!H29,0) -> 18 | I26: =ROUND(I23*Assumptions!I29,0) -> 22 | J26: =ROUND(J23*Assumptions!J29,0) -> 27 | ... AL26: =ROUND(AL23*Assumptions!AL29,0) -> 271
A27: Solo Users | C27: =ROUND(C23*Assumptions!C30,0) -> 0 | D27: =ROUND(D23*Assumptions!D30,0) -> 1 | E27: =ROUND(E23*Assumptions!E30,0) -> 2 | F27: =ROUND(F23*Assumptions!F30,0) -> 18 | G27: =ROUND(G23*Assumptions!G30,0) -> 24 | H27: =ROUND(H23*Assumptions!H30,0) -> 29 | I27: =ROUND(I23*Assumptions!I30,0) -> 37 | J27: =ROUND(J23*Assumptions!J30,0) -> 46 | ... AL27: =ROUND(AL23*Assumptions!AL30,0) -> 1357
A28: Pro Users | C28: =ROUND(C23*Assumptions!C31,0) -> 0 | D28: =ROUND(D23*Assumptions!D31,0) -> 1 | E28: =ROUND(E23*Assumptions!E31,0) -> 2 | F28: =ROUND(F23*Assumptions!F31,0) -> 29 | G28: =ROUND(G23*Assumptions!G31,0) -> 38 | H28: =ROUND(H23*Assumptions!H31,0) -> 47 | I28: =ROUND(I23*Assumptions!I31,0) -> 59 | J28: =ROUND(J23*Assumptions!J31,0) -> 73 | ... AL28: =ROUND(AL23*Assumptions!AL31,0) -> 2442
A29: Pro+ Users | C29: =C23-C26-C27-C28 -> 1 | D29: =D23-D26-D27-D28 -> 1.135 | E29: =E23-E26-E27-E28 -> 1.558225 | F29: =F23-F26-F27-F28 -> 14.808826 | G29: =G23-G26-G27-G28 -> 19.715811 | H29: =H23-H26-H27-H28 -> 23.748705 | I29: =I23-I26-I27-I28 -> 29.998949 | J29: =J23-J26-J27-J28 -> 37.263736 | ... AL29: =AL23-AL26-AL27-AL28 -> 1357.0143
A30: Paying Users | C30: =C27+C28+C29 -> 1 | D30: =D27+D28+D29 -> 3.135 | E30: =E27+E28+E29 -> 5.558225 | F30: =F27+F28+F29 -> 61.808826 | G30: =G27+G28+G29 -> 81.715811 | H30: =H27+H28+H29 -> 99.748705 | I30: =I27+I28+I29 -> 125.99895 | J30: =J27+J28+J29 -> 156.26374 | ... AL30: =AL27+AL28+AL29 -> 5156.0143
A31: Tier Check | C31: =C26+C30 -> 8 | D31: =D26+D30 -> 20.135 | E31: =E26+E30 -> 37.558225 | F31: =F26+F30 -> 72.808826 | G31: =G26+G30 -> 95.715811 | H31: =H26+H30 -> 117.74871 | I31: =I26+I30 -> 147.99895 | J31: =J26+J30 -> 183.26374 | ... AL31: =AL26+AL30 -> 5427.0143
A32: REVENUE
A33: Solo Revenue | C33: =C27*Assumptions!$B$11 -> 0 | D33: =D27*Assumptions!$B$11 -> 15 | E33: =E27*Assumptions!$B$11 -> 30 | F33: =F27*Assumptions!$B$11 -> 270 | G33: =G27*Assumptions!$B$11 -> 360 | H33: =H27*Assumptions!$B$11 -> 435 | I33: =I27*Assumptions!$B$11 -> 555 | J33: =J27*Assumptions!$B$11 -> 690 | ... AL33: =AL27*Assumptions!$B$11 -> 20355
A34: Pro Revenue | C34: =C28*Assumptions!$B$12 -> 0 | D34: =D28*Assumptions!$B$12 -> 35 | E34: =E28*Assumptions!$B$12 -> 70 | F34: =F28*Assumptions!$B$12 -> 1015 | G34: =G28*Assumptions!$B$12 -> 1330 | H34: =H28*Assumptions!$B$12 -> 1645 | I34: =I28*Assumptions!$B$12 -> 2065 | J34: =J28*Assumptions!$B$12 -> 2555 | ... AL34: =AL28*Assumptions!$B$12 -> 85470
A35: Pro+ Revenue | C35: =C29*Assumptions!$B$13 -> 69 | D35: =D29*Assumptions!$B$13 -> 78.315 | E35: =E29*Assumptions!$B$13 -> 107.51752 | F35: =F29*Assumptions!$B$13 -> 1021.809 | G35: =G29*Assumptions!$B$13 -> 1360.391 | H35: =H29*Assumptions!$B$13 -> 1638.6607 | I35: =I29*Assumptions!$B$13 -> 2069.9275 | J35: =J29*Assumptions!$B$13 -> 2571.1978 | ... AL35: =AL29*Assumptions!$B$13 -> 93633.989
A36: Add-on Revenue | C36: =C30*Assumptions!$B$14 -> 0 | D36: =D30*Assumptions!$B$14 -> 0 | E36: =E30*Assumptions!$B$14 -> 0 | F36: =F30*Assumptions!$B$14 -> 0 | G36: =G30*Assumptions!$B$14 -> 0 | H36: =H30*Assumptions!$B$14 -> 0 | I36: =I30*Assumptions!$B$14 -> 0 | J36: =J30*Assumptions!$B$14 -> 0 | ... AL36: =AL30*Assumptions!$B$14 -> 0
A37: Gross Revenue | C37: =C33+C34+C35+C36 -> 69 | D37: =D33+D34+D35+D36 -> 128.315 | E37: =E33+E34+E35+E36 -> 207.51752 | F37: =F33+F34+F35+F36 -> 2306.809 | G37: =G33+G34+G35+G36 -> 3050.391 | H37: =H33+H34+H35+H36 -> 3718.6607 | I37: =I33+I34+I35+I36 -> 4689.9275 | J37: =J33+J34+J35+J36 -> 5816.1978 | ... AL37: =AL33+AL34+AL35+AL36 -> 199458.99
A38: DEDUCTIONS
A39: Failed Payments | C39: =C37*Assumptions!$B$36 -> 2.07 | D39: =D37*Assumptions!$B$36 -> 3.84945 | E39: =E37*Assumptions!$B$36 -> 6.2255257 | F39: =F37*Assumptions!$B$36 -> 69.204269 | G39: =G37*Assumptions!$B$36 -> 91.51173 | H39: =H37*Assumptions!$B$36 -> 111.55982 | I39: =I37*Assumptions!$B$36 -> 140.69782 | J39: =J37*Assumptions!$B$36 -> 174.48593 | ... AL39: =AL37*Assumptions!$B$36 -> 5983.7697
A40: Effective Revenue | C40: =C37-C39 -> 66.93 | D40: =D37-D39 -> 124.46555 | E40: =E37-E39 -> 201.292 | F40: =F37-F39 -> 2237.6047 | G40: =G37-G39 -> 2958.8793 | H40: =H37-H39 -> 3607.1009 | I40: =I37-I39 -> 4549.2297 | J40: =J37-J39 -> 5641.7119 | ... AL40: =AL37-AL39 -> 193475.22
...

Sheet Costs
A1: Cost Model | B1: Units | C1: Jun 2026 | D1: Jul 2026 | E1: Aug 2026 | F1: Sep 2026 | G1: Oct 2026 | H1: Nov 2026 | I1: Dec 2026 | J1: Jan 2027 | K1: Feb 2027 | L1: Mar 2027 | M1: Apr 2027 | N1: May 2027 | O1: Jun 2027 | P1: Jul 2027 | Q1: Aug 2027 | R1: Sep 2027 | S1: Oct 2027 | T1: Nov 2027 | U1: Dec 2027 | V1: Jan 2028 | W1: Feb 2028 | X1: Mar 2028 | Y1: Apr 2028 | Z1: May 2028 | AA1: Jun 2028 | AB1: Jul 2028 | AC1: Aug 2028 | AD1: Sep 2028 | AE1: Oct 2028 | AF1: Nov 2028 | AG1: Dec 2028 | AH1: Jan 2029 | AI1: Feb 2029 | AJ1: Mar 2029 | AK1: Apr 2029 | AL1: May 2029
A2: AI INFERENCE
A3: Total Users | C3: =Revenue!C23 -> 8 | D3: =Revenue!D23 -> 20.135 | E3: =Revenue!E23 -> 37.558225 | F3: =Revenue!F23 -> 72.808826 | G3: =Revenue!G23 -> 95.715811 | H3: =Revenue!H23 -> 117.74871 | I3: =Revenue!I23 -> 147.99895 | J3: =Revenue!J23 -> 183.26374 | ... AL3: =Revenue!AL23 -> 5427.0143
A4: Paying Users | C4: =Revenue!C30 -> 1 | D4: =Revenue!D30 -> 3.135 | E4: =Revenue!E30 -> 5.558225 | F4: =Revenue!F30 -> 61.808826 | G4: =Revenue!G30 -> 81.715811 | H4: =Revenue!H30 -> 99.748705 | I4: =Revenue!I30 -> 125.99895 | J4: =Revenue!J30 -> 156.26374 | ... AL4: =Revenue!AL30 -> 5156.0143
A5: Free Users | C5: =Revenue!C26 -> 7 | D5: =Revenue!D26 -> 17 | E5: =Revenue!E26 -> 32 | F5: =Revenue!F26 -> 11 | G5: =Revenue!G26 -> 14 | H5: =Revenue!H26 -> 18 | I5: =Revenue!I26 -> 22 | J5: =Revenue!J26 -> 27 | ... AL5: =Revenue!AL26 -> 271
A6: Messages (Paying) | C6: =C4*Assumptions!$B$40 -> 150 | D6: =D4*Assumptions!$B$40 -> 470.25 | E6: =E4*Assumptions!$B$40 -> 833.73375 | F6: =F4*Assumptions!$B$40 -> 9271.3238 | G6: =G4*Assumptions!$B$40 -> 12257.372 | H6: =H4*Assumptions!$B$40 -> 14962.306 | I6: =I4*Assumptions!$B$40 -> 18899.842 | J6: =J4*Assumptions!$B$40 -> 23439.56 | ... AL6: =AL4*Assumptions!$B$40 -> 773402.15
A7: Messages (Free) | C7: =C5*Assumptions!$B$40*Assumptions!$B$41 -> 315 | D7: =D5*Assumptions!$B$40*Assumptions!$B$41 -> 765 | E7: =E5*Assumptions!$B$40*Assumptions!$B$41 -> 1440 | F7: =F5*Assumptions!$B$40*Assumptions!$B$41 -> 495 | G7: =G5*Assumptions!$B$40*Assumptions!$B$41 -> 630 | H7: =H5*Assumptions!$B$40*Assumptions!$B$41 -> 810 | I7: =I5*Assumptions!$B$40*Assumptions!$B$41 -> 990 | J7: =J5*Assumptions!$B$40*Assumptions!$B$41 -> 1215 | ... AL7: =AL5*Assumptions!$B$40*Assumptions!$B$41 -> 12195
A8: Total Messages | C8: =C6+C7 -> 465 | D8: =D6+D7 -> 1235.25 | E8: =E6+E7 -> 2273.7337 | F8: =F6+F7 -> 9766.3238 | G8: =G6+G7 -> 12887.372 | H8: =H6+H7 -> 15772.306 | I8: =I6+I7 -> 19889.842 | J8: =J6+J7 -> 24654.56 | ... AL8: =AL6+AL7 -> 785597.15
A9: Total Input Tokens (M) | C9: =C8*Assumptions!$B$42/1000000 -> 1.5345 | D9: =D8*Assumptions!$B$42/1000000 -> 4.076325 | E9: =E8*Assumptions!$B$42/1000000 -> 7.5033214 | F9: =F8*Assumptions!$B$42/1000000 -> 32.228869 | G9: =G8*Assumptions!$B$42/1000000 -> 42.528327 | H9: =H8*Assumptions!$B$42/1000000 -> 52.048609 | I9: =I8*Assumptions!$B$42/1000000 -> 65.63648 | J9: =J8*Assumptions!$B$42/1000000 -> 81.36005 | ... AL9: =AL8*Assumptions!$B$42/1000000 -> 2592.4706
A10: Total Output Tokens (M) | C10: =C8*Assumptions!$B$43/1000000 -> 0.1023 | D10: =D8*Assumptions!$B$43/1000000 -> 0.271755 | E10: =E8*Assumptions!$B$43/1000000 -> 0.50022142 | F10: =F8*Assumptions!$B$43/1000000 -> 2.1485912 | G10: =G8*Assumptions!$B$43/1000000 -> 2.8352218 | H10: =H8*Assumptions!$B$43/1000000 -> 3.4699073 | I10: =I8*Assumptions!$B$43/1000000 -> 4.3757653 | J10: =J8*Assumptions!$B$43/1000000 -> 5.4240033 | ... AL10: =AL8*Assumptions!$B$43/1000000 -> 172.83137
A11: AI Price Factor | C11: =(1-Assumptions!$B$49)^(C1-1) -> 0 | D11: =(1-Assumptions!$B$49)^(D1-1) -> 0 | E11: =(1-Assumptions!$B$49)^(E1-1) -> 0 | F11: =(1-Assumptions!$B$49)^(F1-1) -> 0 | G11: =(1-Assumptions!$B$49)^(G1-1) -> 0 | H11: =(1-Assumptions!$B$49)^(H1-1) -> 0 | I11: =(1-Assumptions!$B$49)^(I1-1) -> 0 | J11: =(1-Assumptions!$B$49)^(J1-1) -> 0 | ... AL11: =(1-Assumptions!$B$49)^(AL1-1) -> 0
A12: Blended Input Price (USD/1M) | C12: =Assumptions!$B$44*Assumptions!$B$45+(1-Assumptions!$B$44)*Assumptions!$B$47 -> 0.8 | D12: =Assumptions!$B$44*Assumptions!$B$45+(1-Assumptions!$B$44)*Assumptions!$B$47 -> 0.8 | E12: =Assumptions!$B$44*Assumptions!$B$45+(1-Assumptions!$B$44)*Assumptions!$B$47 -> 0.8 | F12: =Assumptions!$B$44*Assumptions!$B$45+(1-Assumptions!$B$44)*Assumptions!$B$47 -> 0.8 | G12: =Assumptions!$B$44*Assumptions!$B$45+(1-Assumptions!$B$44)*Assumptions!$B$47 -> 0.8 | H12: =Assumptions!$B$44*Assumptions!$B$45+(1-Assumptions!$B$44)*Assumptions!$B$47 -> 0.8 | I12: =Assumptions!$B$44*Assumptions!$B$45+(1-Assumptions!$B$44)*Assumptions!$B$47 -> 0.8 | J12: =Assumptions!$B$44*Assumptions!$B$45+(1-Assumptions!$B$44)*Assumptions!$B$47 -> 0.8 | ... AL12: =Assumptions!$B$44*Assumptions!$B$45+(1-Assumptions!$B$44)*Assumptions!$B$47 -> 0.8
A13: Blended Output Price (USD/1M) | C13: =Assumptions!$B$44*Assumptions!$B$46+(1-Assumptions!$B$44)*Assumptions!$B$48 -> 4 | D13: =Assumptions!$B$44*Assumptions!$B$46+(1-Assumptions!$B$44)*Assumptions!$B$48 -> 4 | E13: =Assumptions!$B$44*Assumptions!$B$46+(1-Assumptions!$B$44)*Assumptions!$B$48 -> 4 | F13: =Assumptions!$B$44*Assumptions!$B$46+(1-Assumptions!$B$44)*Assumptions!$B$48 -> 4 | G13: =Assumptions!$B$44*Assumptions!$B$46+(1-Assumptions!$B$44)*Assumptions!$B$48 -> 4 | H13: =Assumptions!$B$44*Assumptions!$B$46+(1-Assumptions!$B$44)*Assumptions!$B$48 -> 4 | I13: =Assumptions!$B$44*Assumptions!$B$46+(1-Assumptions!$B$44)*Assumptions!$B$48 -> 4 | J13: =Assumptions!$B$44*Assumptions!$B$46+(1-Assumptions!$B$44)*Assumptions!$B$48 -> 4 | ... AL13: =Assumptions!$B$44*Assumptions!$B$46+(1-Assumptions!$B$44)*Assumptions!$B$48 -> 4
A14: Total AI Cost (CHF) | C14: =(C9*C12*C11+C10*C13*C11)*Assumptions!$B$50 -> 0 | D14: =(D9*D12*D11+D10*D13*D11)*Assumptions!$B$50 -> 0 | E14: =(E9*E12*E11+E10*E13*E11)*Assumptions!$B$50 -> 0 | F14: =(F9*F12*F11+F10*F13*F11)*Assumptions!$B$50 -> 0 | G14: =(G9*G12*G11+G10*G13*G11)*Assumptions!$B$50 -> 0 | H14: =(H9*H12*H11+H10*H13*H11)*Assumptions!$B$50 -> 0 | I14: =(I9*I12*I11+I10*I13*I11)*Assumptions!$B$50 -> 0 | J14: =(J9*J12*J11+J10*J13*J11)*Assumptions!$B$50 -> 0 | ... AL14: =(AL9*AL12*AL11+AL10*AL13*AL11)*Assumptions!$B$50 -> 0
A15: MESSAGING API
A16: Conversations | C16: =C3*Assumptions!$B$53 -> 240 | D16: =D3*Assumptions!$B$53 -> 604.05 | E16: =E3*Assumptions!$B$53 -> 1126.7467 | F16: =F3*Assumptions!$B$53 -> 2184.2648 | G16: =G3*Assumptions!$B$53 -> 2871.4743 | H16: =H3*Assumptions!$B$53 -> 3532.4612 | I16: =I3*Assumptions!$B$53 -> 4439.9685 | J16: =J3*Assumptions!$B$53 -> 5497.9121 | ... AL16: =AL3*Assumptions!$B$53 -> 162810.43
A17: Messaging API Cost (CHF) | C17: =C16*Assumptions!$B$52 -> 12 | D17: =D16*Assumptions!$B$52 -> 30.2025 | E17: =E16*Assumptions!$B$52 -> 56.337337 | F17: =F16*Assumptions!$B$52 -> 109.21324 | G17: =G16*Assumptions!$B$52 -> 143.57372 | H17: =H16*Assumptions!$B$52 -> 176.62306 | I17: =I16*Assumptions!$B$52 -> 221.99842 | J17: =J16*Assumptions!$B$52 -> 274.8956 | ... AL17: =AL16*Assumptions!$B$52 -> 8140.5215
A18: PAYMENT PROCESSING
A19: Payment Processing (CHF) | C19: =Revenue!C37*Assumptions!$B$37+Revenue!C30*Assumptions!$B$38 -> 2.301 | D19: =Revenue!D37*Assumptions!$B$37+Revenue!D30*Assumptions!$B$38 -> 4.661635 | E19: =Revenue!E37*Assumptions!$B$37+Revenue!E30*Assumptions!$B$38 -> 7.6854757 | F19: =Revenue!F37*Assumptions!$B$37+Revenue!F30*Assumptions!$B$38 -> 85.440108 | G19: =Revenue!G37*Assumptions!$B$37+Revenue!G30*Assumptions!$B$38 -> 112.97608 | H19: =Revenue!H37*Assumptions!$B$37+Revenue!H30*Assumptions!$B$38 -> 137.76577 | I19: =Revenue!I37*Assumptions!$B$37+Revenue!I30*Assumptions!$B$38 -> 173.80758 | J19: =Revenue!J37*Assumptions!$B$37+Revenue!J30*Assumptions!$B$38 -> 215.54886 | ... AL19: =Revenue!AL37*Assumptions!$B$37+Revenue!AL30*Assumptions!$B$38 -> 7331.115
A20: STORAGE
A21: Storage Cost (CHF) | C21: =C3*Assumptions!$B$54 -> 0.8 | D21: =D3*Assumptions!$B$54 -> 2.0135 | E21: =E3*Assumptions!$B$54 -> 3.7558225 | F21: =F3*Assumptions!$B$54 -> 7.2808826 | G21: =G3*Assumptions!$B$54 -> 9.5715811 | H21: =H3*Assumptions!$B$54 -> 11.774871 | I21: =I3*Assumptions!$B$54 -> 14.799895 | J21: =J3*Assumptions!$B$54 -> 18.326374 | ... AL21: =AL3*Assumptions!$B$54 -> 542.70143
A22: VARIABLE COSTS
A23: Total Variable Costs | C23: =C14+C17+C19+C21 -> 15.101 | D23: =D14+D17+D19+D21 -> 36.877635 | E23: =E14+E17+E19+E21 -> 67.778636 | F23: =F14+F17+F19+F21 -> 201.93423 | G23: =G14+G17+G19+G21 -> 266.12138 | H23: =H14+H17+H19+H21 -> 326.1637 | I23: =I14+I17+I19+I21 -> 410.6059 | J23: =J14+J17+J19+J21 -> 508.77084 | ... AL23: =AL14+AL17+AL19+AL21 -> 16014.338
A24: Variable Cost per User | C24: =IFERROR(C23/C3,0) -> 1.887625 | D24: =IFERROR(D23/D3,0) -> 1.831519 | E24: =IFERROR(E23/E3,0) -> 1.8046283 | F24: =IFERROR(F23/F3,0) -> 2.7734856 | G24: =IFERROR(G23/G3,0) -> 2.7803283 | H24: =IFERROR(H23/H3,0) -> 2.7699982 | I24: =IFERROR(I23/I3,0) -> 2.7743839 | J24: =IFERROR(J23/J3,0) -> 2.7761675 | ... AL24: =IFERROR(AL23/AL3,0) -> 2.950856
A25: Variable Cost per Paying User | C25: =IFERROR((C23-C26)/C4,0) -> 3.901 | D25: =IFERROR((D23-D26)/D4,0) -> 3.0869649 | E25: =IFERROR((E23-E26)/E4,0) -> 2.9827212 | F25: =IFERROR((F23-F26)/F4,0) -> 2.9823286 | G25: =IFERROR((G23-G26)/G4,0) -> 2.9825486 | H25: =IFERROR((H23-H26)/H4,0) -> 2.9811284 | I25: =IFERROR((I23-I26)/I4,0) -> 2.9794368 | J25: =IFERROR((J23-J26)/J4,0) -> 2.9793914 | ... AL25: =IFERROR((AL23-AL26)/AL4,0) -> 3.021857
A26: Cost of Free Users | C26: =IFERROR((C14+C17+C21)*(C5/C3),0) -> 11.2 | D26: =IFERROR((D14+D17+D21)*(D5/D3),0) -> 27.2 | E26: =IFERROR((E14+E17+E21)*(E5/E3),0) -> 51.2 | F26: =IFERROR((F14+F17+F21)*(F5/F3),0) -> 17.6 | G26: =IFERROR((G14+G17+G21)*(G5/G3),0) -> 22.4 | H26: =IFERROR((H14+H17+H21)*(H5/H3),0) -> 28.8 | I26: =IFERROR((I14+I17+I21)*(I5/I3),0) -> 35.2 | J26: =IFERROR((J14+J17+J21)*(J5/J3),0) -> 43.2 | ... AL26: =IFERROR((AL14+AL17+AL21)*(AL5/AL3),0) -> 433.6
A27: PEOPLE
A28: Co-founder 1 | C28: =Assumptions!C56 -> 5500 | D28: =Assumptions!D56 -> 5500 | E28: =Assumptions!E56 -> 5500 | F28: =Assumptions!F56 -> 5500 | G28: =Assumptions!G56 -> 5500 | H28: =Assumptions!H56 -> 5500 | I28: =Assumptions!I56 -> 5500 | J28: =Assumptions!J56 -> 5500 | ... AL28: =Assumptions!AL56 -> 5500
A29: Co-founder 2 | C29: =Assumptions!C57 -> 0 | D29: =Assumptions!D57 -> 0 | E29: =Assumptions!E57 -> 0 | F29: =Assumptions!F57 -> 0 | G29: =Assumptions!G57 -> 0 | H29: =Assumptions!H57 -> 0 | I29: =Assumptions!I57 -> 0 | J29: =Assumptions!J57 -> 4000 | ... AL29: =Assumptions!AL57 -> 4000
A30: CTO / Engineering | C30: =Assumptions!C58 -> 0 | D30: =Assumptions!D58 -> 0 | E30: =Assumptions!E58 -> 0 | F30: =Assumptions!F58 -> 0 | G30: =Assumptions!G58 -> 0 | H30: =Assumptions!H58 -> 0 | I30: =Assumptions!I58 -> 0 | J30: =Assumptions!J58 -> 1800 | ... AL30: =Assumptions!AL58 -> 1800
A31: Community / Intern | C31: =Assumptions!C59 -> 0 | D31: =Assumptions!D59 -> 0 | E31: =Assumptions!E59 -> 0 | F31: =Assumptions!F59 -> 0 | G31: =Assumptions!G59 -> 0 | H31: =Assumptions!H59 -> 0 | I31: =Assumptions!I59 -> 0 | J31: =Assumptions!J59 -> 0 | ... AL31: =Assumptions!AL59 -> 2000
A32: Total Gross Salaries | C32: =C28+C29+C30+C31 -> 5500 | D32: =D28+D29+D30+D31 -> 5500 | E32: =E28+E29+E30+E31 -> 5500 | F32: =F28+F29+F30+F31 -> 5500 | G32: =G28+G29+G30+G31 -> 5500 | H32: =H28+H29+H30+H31 -> 5500 | I32: =I28+I29+I30+I31 -> 5500 | J32: =J28+J29+J30+J31 -> 11300 | ... AL32: =AL28+AL29+AL30+AL31 -> 13300
A33: Social Charges | C33: =C32*Assumptions!$B$60 -> 880 | D33: =D32*Assumptions!$B$60 -> 880 | E33: =E32*Assumptions!$B$60 -> 880 | F33: =F32*Assumptions!$B$60 -> 880 | G33: =G32*Assumptions!$B$60 -> 880 | H33: =H32*Assumptions!$B$60 -> 880 | I33: =I32*Assumptions!$B$60 -> 880 | J33: =J32*Assumptions!$B$60 -> 1808 | ... AL33: =AL32*Assumptions!$B$60 -> 2128
A34: Total People Cost | C34: =C32+C33 -> 6380 | D34: =D32+D33 -> 6380 | E34: =E32+E33 -> 6380 | F34: =F32+F33 -> 6380 | G34: =G32+G33 -> 6380 | H34: =H32+H33 -> 6380 | I34: =I32+I33 -> 6380 | J34: =J32+J33 -> 13108 | ... AL34: =AL32+AL33 -> 15428
A35: OTHER FIXED COSTS
A36: Legal Retainer | C36: =Assumptions!C62 -> 500 | D36: =Assumptions!D62 -> 500 | E36: =Assumptions!E62 -> 500 | F36: =Assumptions!F62 -> 500 | G36: =Assumptions!G62 -> 500 | H36: =Assumptions!H62 -> 500 | I36: =Assumptions!I62 -> 500 | J36: =Assumptions!J62 -> 500 | ... AL36: =Assumptions!AL62 -> 500
A37: Swiss Hosting | C37: =Assumptions!C63 -> 50 | D37: =Assumptions!D63 -> 50 | E37: =Assumptions!E63 -> 50 | F37: =Assumptions!F63 -> 50 | G37: =Assumptions!G63 -> 50 | H37: =Assumptions!H63 -> 50 | I37: =Assumptions!I63 -> 50 | J37: =Assumptions!J63 -> 50 | ... AL37: =Assumptions!AL63 -> 50
A38: Domain + Tooling + SaaS | C38: =Assumptions!C64 -> 260 | D38: =Assumptions!D64 -> 260 | E38: =Assumptions!E64 -> 260 | F38: =Assumptions!F64 -> 260 | G38: =Assumptions!G64 -> 260 | H38: =Assumptions!H64 -> 260 | I38: =Assumptions!I64 -> 260 | J38: =Assumptions!J64 -> 260 | ... AL38: =Assumptions!AL64 -> 260
A39: Scraper Hosting | C39: =Assumptions!C65 -> 0 | D39: =Assumptions!D65 -> 0 | E39: =Assumptions!E65 -> 0 | F39: =Assumptions!F65 -> 0 | G39: =Assumptions!G65 -> 0 | H39: =Assumptions!H65 -> 0 | I39: =Assumptions!I65 -> 0 | J39: =Assumptions!J65 -> 0 | ... AL39: =Assumptions!AL65 -> 0
A40: Marketing + Merchandising | C40: =Assumptions!C66 -> 200 | D40: =Assumptions!D66 -> 200 | E40: =Assumptions!E66 -> 200 | F40: =Assumptions!F66 -> 200 | G40: =Assumptions!G66 -> 200 | H40: =Assumptions!H66 -> 200 | I40: =Assumptions!I66 -> 500 | J40: =Assumptions!J66 -> 500 | ... AL40: =Assumptions!AL66 -> 500
...

Sheet Unit Economics
A1: Unit Economics | B1: Units | C1: Jun 2026 | D1: Jul 2026 | E1: Aug 2026 | F1: Sep 2026 | G1: Oct 2026 | H1: Nov 2026 | I1: Dec 2026 | J1: Jan 2027 | K1: Feb 2027 | L1: Mar 2027 | M1: Apr 2027 | N1: May 2027 | O1: Jun 2027 | P1: Jul 2027 | Q1: Aug 2027 | R1: Sep 2027 | S1: Oct 2027 | T1: Nov 2027 | U1: Dec 2027 | V1: Jan 2028 | W1: Feb 2028 | X1: Mar 2028 | Y1: Apr 2028 | Z1: May 2028 | AA1: Jun 2028 | AB1: Jul 2028 | AC1: Aug 2028 | AD1: Sep 2028 | AE1: Oct 2028 | AF1: Nov 2028 | AG1: Dec 2028 | AH1: Jan 2029 | AI1: Feb 2029 | AJ1: Mar 2029 | AK1: Apr 2029 | AL1: May 2029
A2: PER-USER ECONOMICS
A3: COGS per Paying User | B3: CHF | C3: =IFERROR((Costs!C23-Costs!C26)/Revenue!C30,0) -> 3.901 | D3: =IFERROR((Costs!D23-Costs!D26)/Revenue!D30,0) -> 3.0869649 | E3: =IFERROR((Costs!E23-Costs!E26)/Revenue!E30,0) -> 2.9827212 | F3: =IFERROR((Costs!F23-Costs!F26)/Revenue!F30,0) -> 2.9823286 | G3: =IFERROR((Costs!G23-Costs!G26)/Revenue!G30,0) -> 2.9825486 | H3: =IFERROR((Costs!H23-Costs!H26)/Revenue!H30,0) -> 2.9811284 | I3: =IFERROR((Costs!I23-Costs!I26)/Revenue!I30,0) -> 2.9794368 | J3: =IFERROR((Costs!J23-Costs!J26)/Revenue!J30,0) -> 2.9793914 | ... AL3: =IFERROR((Costs!AL23-Costs!AL26)/Revenue!AL30,0) -> 3.021857
A4: COGS per User (all) | B4: CHF | C4: =IFERROR(Costs!C23/Revenue!C23,0) -> 1.887625 | D4: =IFERROR(Costs!D23/Revenue!D23,0) -> 1.831519 | E4: =IFERROR(Costs!E23/Revenue!E23,0) -> 1.8046283 | F4: =IFERROR(Costs!F23/Revenue!F23,0) -> 2.7734856 | G4: =IFERROR(Costs!G23/Revenue!G23,0) -> 2.7803283 | H4: =IFERROR(Costs!H23/Revenue!H23,0) -> 2.7699982 | I4: =IFERROR(Costs!I23/Revenue!I23,0) -> 2.7743839 | J4: =IFERROR(Costs!J23/Revenue!J23,0) -> 2.7761675 | ... AL4: =IFERROR(Costs!AL23/Revenue!AL23,0) -> 2.950856
A5: Cost of Free Users (total) | B5: CHF | C5: =Costs!C26 -> 11.2 | D5: =Costs!D26 -> 27.2 | E5: =Costs!E26 -> 51.2 | F5: =Costs!F26 -> 17.6 | G5: =Costs!G26 -> 22.4 | H5: =Costs!H26 -> 28.8 | I5: =Costs!I26 -> 35.2 | J5: =Costs!J26 -> 43.2 | ... AL5: =Costs!AL26 -> 433.6
A6: Cost of Free Users (per free user) | B6: CHF | C6: =IFERROR(Costs!C26/Revenue!C26,0) -> 1.6 | D6: =IFERROR(Costs!D26/Revenue!D26,0) -> 1.6 | E6: =IFERROR(Costs!E26/Revenue!E26,0) -> 1.6 | F6: =IFERROR(Costs!F26/Revenue!F26,0) -> 1.6 | G6: =IFERROR(Costs!G26/Revenue!G26,0) -> 1.6 | H6: =IFERROR(Costs!H26/Revenue!H26,0) -> 1.6 | I6: =IFERROR(Costs!I26/Revenue!I26,0) -> 1.6 | J6: =IFERROR(Costs!J26/Revenue!J26,0) -> 1.6 | ... AL6: =IFERROR(Costs!AL26/Revenue!AL26,0) -> 1.6
A7: MARGINS
A8: Effective Revenue | B8: CHF | C8: =Revenue!C40 -> 66.93 | D8: =Revenue!D40 -> 124.46555 | E8: =Revenue!E40 -> 201.292 | F8: =Revenue!F40 -> 2237.6047 | G8: =Revenue!G40 -> 2958.8793 | H8: =Revenue!H40 -> 3607.1009 | I8: =Revenue!I40 -> 4549.2297 | J8: =Revenue!J40 -> 5641.7119 | ... AL8: =Revenue!AL40 -> 193475.22
A9: Total COGS | B9: CHF | C9: =Costs!C23 -> 15.101 | D9: =Costs!D23 -> 36.877635 | E9: =Costs!E23 -> 67.778636 | F9: =Costs!F23 -> 201.93423 | G9: =Costs!G23 -> 266.12138 | H9: =Costs!H23 -> 326.1637 | I9: =Costs!I23 -> 410.6059 | J9: =Costs!J23 -> 508.77084 | ... AL9: =Costs!AL23 -> 16014.338
A10: Gross Profit | B10: CHF | C10: =C8-C9 -> 51.829 | D10: =D8-D9 -> 87.587915 | E10: =E8-E9 -> 133.51336 | F10: =F8-F9 -> 2035.6705 | G10: =G8-G9 -> 2692.7579 | H10: =H8-H9 -> 3280.9372 | I10: =I8-I9 -> 4138.6238 | J10: =J8-J9 -> 5132.941 | ... AL10: =AL8-AL9 -> 177460.88
A11: Gross Margin % | B11: % | C11: =IFERROR(C10/C8,0) -> 0.77437621 | D11: =IFERROR(D10/D8,0) -> 0.70371211 | E11: =IFERROR(E10/E8,0) -> 0.66328202 | F11: =IFERROR(F10/F8,0) -> 0.90975429 | G11: =IFERROR(G10/G8,0) -> 0.91006007 | H11: =IFERROR(H10/H8,0) -> 0.90957733 | I11: =IFERROR(I10/I8,0) -> 0.90974166 | J11: =IFERROR(J10/J8,0) -> 0.90981978 | ... AL11: =IFERROR(AL10/AL8,0) -> 0.91722796
A12: CUSTOMER ACQUISITION COST
A13: Marketing Spend | B13: CHF | C13: =Costs!C40 -> 200 | D13: =Costs!D40 -> 200 | E13: =Costs!E40 -> 200 | F13: =Costs!F40 -> 200 | G13: =Costs!G40 -> 200 | H13: =Costs!H40 -> 200 | I13: =Costs!I40 -> 500 | J13: =Costs!J40 -> 500 | ... AL13: =Costs!AL40 -> 500
A14: Travel + Events | B14: CHF | C14: =Costs!C41 -> 300 | D14: =Costs!D41 -> 300 | E14: =Costs!E41 -> 300 | F14: =Costs!F41 -> 300 | G14: =Costs!G41 -> 300 | H14: =Costs!H41 -> 300 | I14: =Costs!I41 -> 300 | J14: =Costs!J41 -> 300 | ... AL14: =Costs!AL41 -> 300
A15: Co-founder Time (acq share) | B15: CHF | C15: =(Costs!C28+Costs!C29)*Assumptions!$B$86 -> 1650 | D15: =(Costs!D28+Costs!D29)*Assumptions!$B$86 -> 1650 | E15: =(Costs!E28+Costs!E29)*Assumptions!$B$86 -> 1650 | F15: =(Costs!F28+Costs!F29)*Assumptions!$B$86 -> 1650 | G15: =(Costs!G28+Costs!G29)*Assumptions!$B$86 -> 1650 | H15: =(Costs!H28+Costs!H29)*Assumptions!$B$86 -> 1650 | I15: =(Costs!I28+Costs!I29)*Assumptions!$B$86 -> 1650 | J15: =(Costs!J28+Costs!J29)*Assumptions!$B$86 -> 2850 | ... AL15: =(Costs!AL28+Costs!AL29)*Assumptions!$B$86 -> 2850
A16: Total Acquisition Cost | B16: CHF | C16: =C13+C14+C15 -> 2150 | D16: =D13+D14+D15 -> 2150 | E16: =E13+E14+E15 -> 2150 | F16: =F13+F14+F15 -> 2150 | G16: =G13+G14+G15 -> 2150 | H16: =H13+H14+H15 -> 2150 | I16: =I13+I14+I15 -> 2450 | J16: =J13+J14+J15 -> 3650 | ... AL16: =AL13+AL14+AL15 -> 3650
A17: New Paying Users This Month | C17: =MAX(Revenue!C13*(1-Assumptions!C29),0) -> 1.2 | D17: =MAX(Revenue!D13*(1-Assumptions!D29),0) -> 1.8 | E17: =MAX(Revenue!E13*(1-Assumptions!E29),0) -> 2.55 | F17: =MAX(Revenue!F13*(1-Assumptions!F29),0) -> 30.175204 | G17: =MAX(Revenue!G13*(1-Assumptions!G29),0) -> 17.478375 | H17: =MAX(Revenue!H13*(1-Assumptions!H29),0) -> 16.151071 | I17: =MAX(Revenue!I13*(1-Assumptions!I29),0) -> 20.216543 | J17: =MAX(Revenue!J13*(1-Assumptions!J29),0) -> 23.16669 | ... AL17: =MAX(Revenue!AL13*(1-Assumptions!AL29),0) -> 0
A18: Fully Loaded CAC | B18: CHF | C18: =IFERROR(C16/C17,0) -> 1791.6667 | D18: =IFERROR(D16/D17,0) -> 1194.4444 | E18: =IFERROR(E16/E17,0) -> 843.13725 | F18: =IFERROR(F16/F17,0) -> 71.250553 | G18: =IFERROR(G16/G17,0) -> 123.00915 | H18: =IFERROR(H16/H17,0) -> 133.11811 | I18: =IFERROR(I16/I17,0) -> 121.18788 | J18: =IFERROR(J16/J17,0) -> 157.5538 | ... AL18: =IFERROR(AL16/AL17,0) -> 0
A19: LIFETIME VALUE
A20: ARPU | B20: CHF | C20: =Revenue!C46 -> 69 | D20: =Revenue!D46 -> 40.929825 | E20: =Revenue!E46 -> 37.335215 | F20: =Revenue!F46 -> 37.321676 | G20: =Revenue!G46 -> 37.329263 | H20: =Revenue!H46 -> 37.28029 | I20: =Revenue!I46 -> 37.221957 | J20: =Revenue!J46 -> 37.220394 | ... AL20: =Revenue!AL46 -> 38.684724
A21: Monthly Churn Rate | B21: % | C21: =Revenue!C19 -> 0.1 | D21: =Revenue!D19 -> 0.12 | E21: =Revenue!E19 -> 0.12 | F21: =Revenue!F19 -> 0.1 | G21: =Revenue!G19 -> 0.1 | H21: =Revenue!H19 -> 0.1 | I21: =Revenue!I19 -> 0.07 | J21: =Revenue!J19 -> 0.07 | ... AL21: =Revenue!AL19 -> 0.05
A22: LTV | B22: CHF | C22: =IFERROR(C20/C21,0) -> 690 | D22: =IFERROR(D20/D21,0) -> 341.08187 | E22: =IFERROR(E20/E21,0) -> 311.12679 | F22: =IFERROR(F20/F21,0) -> 373.21676 | G22: =IFERROR(G20/G21,0) -> 373.29263 | H22: =IFERROR(H20/H21,0) -> 372.8029 | I22: =IFERROR(I20/I21,0) -> 531.74225 | J22: =IFERROR(J20/J21,0) -> 531.71991 | ... AL22: =IFERROR(AL20/AL21,0) -> 773.69447
A23: LTV/CAC Ratio | C23: =IFERROR(C22/C18,0) -> 0.38511628 | D23: =IFERROR(D22/D18,0) -> 0.28555692 | E23: =IFERROR(E22/E18,0) -> 0.36901085 | F23: =IFERROR(F22/F18,0) -> 5.2380893 | G23: =IFERROR(G22/G18,0) -> 3.0346738 | H23: =IFERROR(H22/H18,0) -> 2.8005423 | I23: =IFERROR(I22/I18,0) -> 4.387751 | J23: =IFERROR(J22/J18,0) -> 3.3748466 | ... AL23: =IFERROR(AL22/AL18,0) -> 0
A24: ANNUAL SUMMARY
A25: Y1 Avg Gross Margin % | B25: =AVERAGE(C11:N11) -> 0.86067206
A26: Y2 Avg Gross Margin % | B26: =AVERAGE(O11:Z11) -> 0.91722509
A27: Y3 Avg Gross Margin % | B27: =AVERAGE(AA11:AL11) -> 0.91722547
A28: Y1 Avg CAC | B28: =IFERROR(SUM(C16:N16)/SUM(C17:N17),0) -> 128.28681
A29: Y3 LTV/CAC | B29: =AL23 -> 0
A30: Y3 ARPU | B30: =AL20 -> 38.684724

Sheet P&L
A1: Profit & Loss | B1: Units | C1: Jun 2026 | D1: Jul 2026 | E1: Aug 2026 | F1: Sep 2026 | G1: Oct 2026 | H1: Nov 2026 | I1: Dec 2026 | J1: Jan 2027 | K1: Feb 2027 | L1: Mar 2027 | M1: Apr 2027 | N1: May 2027 | O1: Jun 2027 | P1: Jul 2027 | Q1: Aug 2027 | R1: Sep 2027 | S1: Oct 2027 | T1: Nov 2027 | U1: Dec 2027 | V1: Jan 2028 | W1: Feb 2028 | X1: Mar 2028 | Y1: Apr 2028 | Z1: May 2028 | AA1: Jun 2028 | AB1: Jul 2028 | AC1: Aug 2028 | AD1: Sep 2028 | AE1: Oct 2028 | AF1: Nov 2028 | AG1: Dec 2028 | AH1: Jan 2029 | AI1: Feb 2029 | AJ1: Mar 2029 | AK1: Apr 2029 | AL1: May 2029
A2: REVENUE
A3: Gross Revenue | C3: =Revenue!C37 -> 69 | D3: =Revenue!D37 -> 128.315 | E3: =Revenue!E37 -> 207.51752 | F3: =Revenue!F37 -> 2306.809 | G3: =Revenue!G37 -> 3050.391 | H3: =Revenue!H37 -> 3718.6607 | I3: =Revenue!I37 -> 4689.9275 | J3: =Revenue!J37 -> 5816.1978 | ... AL3: =Revenue!AL37 -> 199458.99
A4: Failed Payments | C4: =Revenue!C39 -> 2.07 | D4: =Revenue!D39 -> 3.84945 | E4: =Revenue!E39 -> 6.2255257 | F4: =Revenue!F39 -> 69.204269 | G4: =Revenue!G39 -> 91.51173 | H4: =Revenue!H39 -> 111.55982 | I4: =Revenue!I39 -> 140.69782 | J4: =Revenue!J39 -> 174.48593 | ... AL4: =Revenue!AL39 -> 5983.7697
A5: Net Revenue | C5: =Revenue!C40 -> 66.93 | D5: =Revenue!D40 -> 124.46555 | E5: =Revenue!E40 -> 201.292 | F5: =Revenue!F40 -> 2237.6047 | G5: =Revenue!G40 -> 2958.8793 | H5: =Revenue!H40 -> 3607.1009 | I5: =Revenue!I40 -> 4549.2297 | J5: =Revenue!J40 -> 5641.7119 | ... AL5: =Revenue!AL40 -> 193475.22
A6: COGS
A7: AI Inference | C7: =Costs!C14 -> 0 | D7: =Costs!D14 -> 0 | E7: =Costs!E14 -> 0 | F7: =Costs!F14 -> 0 | G7: =Costs!G14 -> 0 | H7: =Costs!H14 -> 0 | I7: =Costs!I14 -> 0 | J7: =Costs!J14 -> 0 | ... AL7: =Costs!AL14 -> 0
A8: Messaging API | C8: =Costs!C17 -> 12 | D8: =Costs!D17 -> 30.2025 | E8: =Costs!E17 -> 56.337337 | F8: =Costs!F17 -> 109.21324 | G8: =Costs!G17 -> 143.57372 | H8: =Costs!H17 -> 176.62306 | I8: =Costs!I17 -> 221.99842 | J8: =Costs!J17 -> 274.8956 | ... AL8: =Costs!AL17 -> 8140.5215
A9: Payment Processing | C9: =Costs!C19 -> 2.301 | D9: =Costs!D19 -> 4.661635 | E9: =Costs!E19 -> 7.6854757 | F9: =Costs!F19 -> 85.440108 | G9: =Costs!G19 -> 112.97608 | H9: =Costs!H19 -> 137.76577 | I9: =Costs!I19 -> 173.80758 | J9: =Costs!J19 -> 215.54886 | ... AL9: =Costs!AL19 -> 7331.115
A10: Storage | C10: =Costs!C21 -> 0.8 | D10: =Costs!D21 -> 2.0135 | E10: =Costs!E21 -> 3.7558225 | F10: =Costs!F21 -> 7.2808826 | G10: =Costs!G21 -> 9.5715811 | H10: =Costs!H21 -> 11.774871 | I10: =Costs!I21 -> 14.799895 | J10: =Costs!J21 -> 18.326374 | ... AL10: =Costs!AL21 -> 542.70143
A11: Total COGS | C11: =C7+C8+C9+C10 -> 15.101 | D11: =D7+D8+D9+D10 -> 36.877635 | E11: =E7+E8+E9+E10 -> 67.778636 | F11: =F7+F8+F9+F10 -> 201.93423 | G11: =G7+G8+G9+G10 -> 266.12138 | H11: =H7+H8+H9+H10 -> 326.1637 | I11: =I7+I8+I9+I10 -> 410.6059 | J11: =J7+J8+J9+J10 -> 508.77084 | ... AL11: =AL7+AL8+AL9+AL10 -> 16014.338
A12: GROSS PROFIT | C12: =C5-C11 -> 51.829 | D12: =D5-D11 -> 87.587915 | E12: =E5-E11 -> 133.51336 | F12: =F5-F11 -> 2035.6705 | G12: =G5-G11 -> 2692.7579 | H12: =H5-H11 -> 3280.9372 | I12: =I5-I11 -> 4138.6238 | J12: =J5-J11 -> 5132.941 | ... AL12: =AL5-AL11 -> 177460.88
A13: Gross Margin % | B13: % | C13: =IFERROR(C12/C5,0) -> 0.77437621 | D13: =IFERROR(D12/D5,0) -> 0.70371211 | E13: =IFERROR(E12/E5,0) -> 0.66328202 | F13: =IFERROR(F12/F5,0) -> 0.90975429 | G13: =IFERROR(G12/G5,0) -> 0.91006007 | H13: =IFERROR(H12/H5,0) -> 0.90957733 | I13: =IFERROR(I12/I5,0) -> 0.90974166 | J13: =IFERROR(J12/J5,0) -> 0.90981978 | ... AL13: =IFERROR(AL12/AL5,0) -> 0.91722796
A14: OPERATING EXPENSES
A15: People Costs | C15: =Costs!C34 -> 6380 | D15: =Costs!D34 -> 6380 | E15: =Costs!E34 -> 6380 | F15: =Costs!F34 -> 6380 | G15: =Costs!G34 -> 6380 | H15: =Costs!H34 -> 6380 | I15: =Costs!I34 -> 6380 | J15: =Costs!J34 -> 13108 | ... AL15: =Costs!AL34 -> 15428
A16: Legal | C16: =Costs!C36 -> 500 | D16: =Costs!D36 -> 500 | E16: =Costs!E36 -> 500 | F16: =Costs!F36 -> 500 | G16: =Costs!G36 -> 500 | H16: =Costs!H36 -> 500 | I16: =Costs!I36 -> 500 | J16: =Costs!J36 -> 500 | ... AL16: =Costs!AL36 -> 500
A17: Infrastructure | C17: =Costs!C37+Costs!C38+Costs!C39 -> 310 | D17: =Costs!D37+Costs!D38+Costs!D39 -> 310 | E17: =Costs!E37+Costs!E38+Costs!E39 -> 310 | F17: =Costs!F37+Costs!F38+Costs!F39 -> 310 | G17: =Costs!G37+Costs!G38+Costs!G39 -> 310 | H17: =Costs!H37+Costs!H38+Costs!H39 -> 310 | I17: =Costs!I37+Costs!I38+Costs!I39 -> 310 | J17: =Costs!J37+Costs!J38+Costs!J39 -> 310 | ... AL17: =Costs!AL37+Costs!AL38+Costs!AL39 -> 310
A18: Marketing + Merchandising | C18: =Costs!C40 -> 200 | D18: =Costs!D40 -> 200 | E18: =Costs!E40 -> 200 | F18: =Costs!F40 -> 200 | G18: =Costs!G40 -> 200 | H18: =Costs!H40 -> 200 | I18: =Costs!I40 -> 500 | J18: =Costs!J40 -> 500 | ... AL18: =Costs!AL40 -> 500
A19: Travel + Events | C19: =Costs!C41 -> 300 | D19: =Costs!D41 -> 300 | E19: =Costs!E41 -> 300 | F19: =Costs!F41 -> 300 | G19: =Costs!G41 -> 300 | H19: =Costs!H41 -> 300 | I19: =Costs!I41 -> 300 | J19: =Costs!J41 -> 300 | ... AL19: =Costs!AL41 -> 300
A20: Insurance | C20: =Costs!C42+Costs!C43 -> 167 | D20: =Costs!D42+Costs!D43 -> 167 | E20: =Costs!E42+Costs!E43 -> 167 | F20: =Costs!F42+Costs!F43 -> 167 | G20: =Costs!G42+Costs!G43 -> 167 | H20: =Costs!H42+Costs!H43 -> 167 | I20: =Costs!I42+Costs!I43 -> 167 | J20: =Costs!J42+Costs!J43 -> 167 | ... AL20: =Costs!AL42+Costs!AL43 -> 167
A21: Accounting + Compliance | C21: =Costs!C44+Costs!C45+Costs!C46 -> 483 | D21: =Costs!D44+Costs!D45+Costs!D46 -> 483 | E21: =Costs!E44+Costs!E45+Costs!E46 -> 483 | F21: =Costs!F44+Costs!F45+Costs!F46 -> 483 | G21: =Costs!G44+Costs!G45+Costs!G46 -> 483 | H21: =Costs!H44+Costs!H45+Costs!H46 -> 483 | I21: =Costs!I44+Costs!I45+Costs!I46 -> 483 | J21: =Costs!J44+Costs!J45+Costs!J46 -> 483 | ... AL21: =Costs!AL44+Costs!AL45+Costs!AL46 -> 483
A22: Office / IT / Other | C22: =Costs!C47+Costs!C48+Costs!C49 -> 3000
A23: Contingency | C23: =Costs!C60 -> 1135.5101 | D23: =Costs!D60 -> 877.68776 | E23: =Costs!E60 -> 880.77786 | F23: =Costs!F60 -> 894.19342 | G23: =Costs!G60 -> 900.61214 | H23: =Costs!H60 -> 906.61637 | I23: =Costs!I60 -> 1145.0606 | J23: =Costs!J60 -> 1627.6771 | ... AL23: =Costs!AL60 -> 3410.2338
A24: Total OpEx | C24: =SUM(C15:C23) -> 12475.51 | D24: =SUM(D15:D23) -> 9217.6878 | E24: =SUM(E15:E23) -> 9220.7779 | F24: =SUM(F15:F23) -> 9234.1934 | G24: =SUM(G15:G23) -> 9240.6121 | H24: =SUM(H15:H23) -> 9246.6164 | I24: =SUM(I15:I23) -> 9785.0606 | J24: =SUM(J15:J23) -> 16995.677 | ... AL24: =SUM(AL15:AL23) -> 21098.234
A25: ONE-TIME COSTS
A26: Formation Fees | C26: =Costs!C53 -> 7000 | D26: =Costs!D53 -> 0 | E26: =Costs!E53 -> 0 | F26: =Costs!F53 -> 0 | G26: =Costs!G53 -> 0 | H26: =Costs!H53 -> 0 | I26: =Costs!I53 -> 0 | J26: =Costs!J53 -> 0 | ... AL26: =Costs!AL53 -> 0
A27: Legal Opinions | C27: =Costs!C54 -> 5000 | D27: =Costs!D54 -> 5000 | E27: =Costs!E54 -> 0 | F27: =Costs!F54 -> 0 | G27: =Costs!G54 -> 0 | H27: =Costs!H54 -> 0 | I27: =Costs!I54 -> 0 | J27: =Costs!J54 -> 0 | ... AL27: =Costs!AL54 -> 0
A28: Design Consulting | C28: =Costs!C55 -> 3000 | D28: =Costs!D55 -> 0 | E28: =Costs!E55 -> 5000 | F28: =Costs!F55 -> 0 | G28: =Costs!G55 -> 0 | H28: =Costs!H55 -> 0 | I28: =Costs!I55 -> 0 | J28: =Costs!J55 -> 0 | ... AL28: =Costs!AL55 -> 0
A29: Architecture & Tech Review | C29: =Costs!C56 -> 5000 | D29: =Costs!D56 -> 0 | E29: =Costs!E56 -> 0 | F29: =Costs!F56 -> 0 | G29: =Costs!G56 -> 0 | H29: =Costs!H56 -> 0 | I29: =Costs!I56 -> 0 | J29: =Costs!J56 -> 0 | ... AL29: =Costs!AL56 -> 0
A30: Fundraising Legal | C30: =Costs!C57 -> 8000 | D30: =Costs!D57 -> 0 | E30: =Costs!E57 -> 0 | F30: =Costs!F57 -> 0 | G30: =Costs!G57 -> 0 | H30: =Costs!H57 -> 0 | I30: =Costs!I57 -> 0 | J30: =Costs!J57 -> 0 | ... AL30: =Costs!AL57 -> 0
A31: Total One-Time | C31: =Costs!C58 -> 28000 | D31: =Costs!D58 -> 5000 | E31: =Costs!E58 -> 5000 | F31: =Costs!F58 -> 0 | G31: =Costs!G58 -> 0 | H31: =Costs!H58 -> 0 | I31: =Costs!I58 -> 0 | J31: =Costs!J58 -> 0 | ... AL31: =Costs!AL58 -> 0
A32: TOTAL EXPENSES | C32: =C11+C24+C31 -> 40490.611 | D32: =D11+D24+D31 -> 14254.565 | E32: =E11+E24+E31 -> 14288.556 | F32: =F11+F24+F31 -> 9436.1277 | G32: =G11+G24+G31 -> 9506.7335 | H32: =H11+H24+H31 -> 9572.7801 | I32: =I11+I24+I31 -> 10195.666 | J32: =J11+J24+J31 -> 17504.448 | ... AL32: =AL11+AL24+AL31 -> 37112.572
A33: BOTTOM LINE
A34: EBITDA | C34: =C5-C11-C24 -> -12423.681 | D34: =D5-D11-D24 -> -9130.0998 | E34: =E5-E11-E24 -> -9087.2645 | F34: =F5-F11-F24 -> -7198.523 | G34: =G5-G11-G24 -> -6547.8543 | H34: =H5-H11-H24 -> -5965.6792 | I34: =I5-I11-I24 -> -5646.4368 | J34: =J5-J11-J24 -> -11862.736 | ... AL34: =AL5-AL11-AL24 -> 156362.65
A35: Pre-Tax Income | C35: =C5-C32 -> -40423.681 | D35: =D5-D32 -> -14130.1 | E35: =E5-E32 -> -14087.265 | F35: =F5-F32 -> -7198.523 | G35: =G5-G32 -> -6547.8543 | H35: =H5-H32 -> -5965.6792 | I35: =I5-I32 -> -5646.4368 | J35: =J5-J32 -> -11862.736 | ... AL35: =AL5-AL32 -> 156362.65
A36: Cumulative Pre-Tax Income | C36: =C35 -> -40423.681 | D36: =C36+D35 -> -54553.781 | E36: =D36+E35 -> -68641.045 | F36: =E36+F35 -> -75839.568 | G36: =F36+G35 -> -82387.423 | H36: =G36+H35 -> -88353.102 | I36: =H36+I35 -> -93999.539 | J36: =I36+J35 -> -105862.27 | K36: =J36+K35 -> -116406.71 | ... AL36: =AK36+AL35 -> 1350710.3
A37: Corporate Tax | C37: =IF(C36>0,C35*Assumptions!$B$85,0) -> 0 | D37: =IF(D36>0,D35*Assumptions!$B$85,0) -> 0 | E37: =IF(E36>0,E35*Assumptions!$B$85,0) -> 0 | F37: =IF(F36>0,F35*Assumptions!$B$85,0) -> 0 | G37: =IF(G36>0,G35*Assumptions!$B$85,0) -> 0 | H37: =IF(H36>0,H35*Assumptions!$B$85,0) -> 0 | I37: =IF(I36>0,I35*Assumptions!$B$85,0) -> 0 | J37: =IF(J36>0,J35*Assumptions!$B$85,0) -> 0 | ... AL37: =IF(AL36>0,AL35*Assumptions!$B$85,0) -> 21890.771
A38: NET INCOME (LOSS) | C38: =C35-C37 -> -40423.681 | D38: =D35-D37 -> -14130.1 | E38: =E35-E37 -> -14087.265 | F38: =F35-F37 -> -7198.523 | G38: =G35-G37 -> -6547.8543 | H38: =H35-H37 -> -5965.6792 | I38: =I35-I37 -> -5646.4368 | J38: =J35-J37 -> -11862.736 | ... AL38: =AL35-AL37 -> 134471.88
A39: ANNUAL SUMMARY
A40: Y1 Net Revenue | B40: =SUM(C5:N5) -> 58756.629
...

Sheet Cash Flow
A1: Cash Flow | B1: Units | C1: Jun 2026 | D1: Jul 2026 | E1: Aug 2026 | F1: Sep 2026 | G1: Oct 2026 | H1: Nov 2026 | I1: Dec 2026 | J1: Jan 2027 | K1: Feb 2027 | L1: Mar 2027 | M1: Apr 2027 | N1: May 2027 | O1: Jun 2027 | P1: Jul 2027 | Q1: Aug 2027 | R1: Sep 2027 | S1: Oct 2027 | T1: Nov 2027 | U1: Dec 2027 | V1: Jan 2028 | W1: Feb 2028 | X1: Mar 2028 | Y1: Apr 2028 | Z1: May 2028 | AA1: Jun 2028 | AB1: Jul 2028 | AC1: Aug 2028 | AD1: Sep 2028 | AE1: Oct 2028 | AF1: Nov 2028 | AG1: Dec 2028 | AH1: Jan 2029 | AI1: Feb 2029 | AJ1: Mar 2029 | AK1: Apr 2029 | AL1: May 2029
A2: CASH FLOW
A3: Revenue Cash In | B3: CHF | C3: =Revenue!C40 -> 66.93 | D3: =Revenue!D40 -> 124.46555 | E3: =Revenue!E40 -> 201.292 | F3: =Revenue!F40 -> 2237.6047 | G3: =Revenue!G40 -> 2958.8793 | H3: =Revenue!H40 -> 3607.1009 | I3: =Revenue!I40 -> 4549.2297 | J3: =Revenue!J40 -> 5641.7119 | ... AL3: =Revenue!AL40 -> 193475.22
A4: Total Costs Out | B4: CHF | C4: =Costs!C62 -> 40490.611 | D4: =Costs!D62 -> 14654.565 | E4: =Costs!E62 -> 14688.556 | F4: =Costs!F62 -> 9836.1277 | G4: =Costs!G62 -> 9906.7335 | H4: =Costs!H62 -> 9972.7801 | I4: =Costs!I62 -> 12595.666 | J4: =Costs!J62 -> 17904.448 | ... AL4: =Costs!AL62 -> 37512.572
A5: VAT Remitted | B5: CHF | C5: 0 | D5: 0 | E5: =SUM(Revenue!C42:E42) -> 29.424321 | F5: 0 | G5: 0 | H5: =SUM(Revenue!F42:H42) -> 659.65807 | I5: 0 | J5: 0 | K5: =SUM(Revenue!I42:K42) -> 1296.2464 | L5: 0 | M5: 0 | N5: =SUM(Revenue!L42:N42) -> 2417.3419 | O5: 0 | P5: 0 | Q5: =SUM(Revenue!O42:Q42) -> 5038.6519 | R5: 0 | S5: 0 | T5: =SUM(Revenue!R42:T42) -> 8819.8285 | U5: 0 | V5: 0 | W5: =SUM(Revenue!U42:W42) -> 13031.938 | X5: 0 | Y5: 0 | Z5: =SUM(Revenue!X42:Z42) -> 16452.894 | AA5: 0 | AB5: 0 | AC5: =SUM(Revenue!AA42:AC42) -> 20395.518 | AD5: 0 | AE5: 0 | AF5: =SUM(Revenue!AD42:AF42) -> 25307.603 | AG5: 0 | AH5: 0 | AI5: =SUM(Revenue!AG42:AI42) -> 31941.253 | AJ5: 0 | AK5: 0 | AL5: =SUM(Revenue!AJ42:AL42) -> 40326.644
A6: Corporate Tax Paid | B6: CHF | C6: 0 | D6: 0 | E6: =SUM('P&L'!C37:E37) -> 0 | F6: 0 | G6: 0 | H6: =SUM('P&L'!F37:H37) -> 0 | I6: 0 | J6: 0 | K6: =SUM('P&L'!I37:K37) -> 0 | L6: 0 | M6: 0 | N6: =SUM('P&L'!L37:N37) -> 0 | O6: 0 | P6: 0 | Q6: =SUM('P&L'!O37:Q37) -> 0 | R6: 0 | S6: 0 | T6: =SUM('P&L'!R37:T37) -> 0 | U6: 0 | V6: 0 | W6: =SUM('P&L'!U37:W37) -> 5229.1215 | X6: 0 | Y6: 0 | Z6: =SUM('P&L'!X37:Z37) -> 19752.772 | AA6: 0 | AB6: 0 | AC6: =SUM('P&L'!AA37:AC37) -> 26448.774 | AD6: 0 | AE6: 0 | AF6: =SUM('P&L'!AD37:AF37) -> 34790.319 | AG6: 0 | AH6: 0 | AI6: =SUM('P&L'!AG37:AI37) -> 46056.01 | AJ6: 0 | AK6: 0 | AL6: =SUM('P&L'!AJ37:AL37) -> 60297.351
A7: Round 2 Injection | B7: CHF | C7: 0 | D7: 0 | E7: 0 | F7: 0 | G7: 0 | H7: 0 | I7: 0 | J7: 0 | K7: 0 | L7: 0 | M7: 0 | N7: 0 | O7: 0 | P7: 0 | Q7: 0 | R7: 0 | S7: 0 | T7: 0 | U7: 0 | V7: 0 | W7: 0 | X7: 0 | Y7: 0 | Z7: 0 | AA7: 0 | AB7: 0 | AC7: 0 | AD7: 0 | AE7: 0 | AF7: 0 | AG7: 0 | AH7: 0 | AI7: 0 | AJ7: 0 | AK7: 0 | AL7: 0
A8: Net Monthly Cash Flow | B8: CHF | C8: =C3-C4-C5-C6+C7 -> -40423.681 | D8: =D3-D4-D5-D6+D7 -> -14530.1 | E8: =E3-E4-E5-E6+E7 -> -14516.689 | F8: =F3-F4-F5-F6+F7 -> -7598.523 | G8: =G3-G4-G5-G6+G7 -> -6947.8543 | H8: =H3-H4-H5-H6+H7 -> -7025.3373 | I8: =I3-I4-I5-I6+I7 -> -8046.4368 | J8: =J3-J4-J5-J6+J7 -> -12262.736 | ... AL8: =AL3-AL4-AL5-AL6+AL7 -> 55338.652
A9: CASH POSITION
A10: Opening Cash | B10: CHF | C10: =Assumptions!$B$8 -> 113000 | D10: =C11 -> 72576.319 | E10: =D11 -> 58046.219 | F10: =E11 -> 43529.53 | G10: =F11 -> 35931.007 | H10: =G11 -> 28983.153 | I10: =H11 -> 21957.816 | J10: =I11 -> 13911.379 | K10: =J11 -> 1648.6429 | ... AL10: =AK11 -> 1034080.3
A11: Closing Cash | B11: CHF | C11: =C10+C8 -> 72576.319 | D11: =D10+D8 -> 58046.219 | E11: =E10+E8 -> 43529.53 | F11: =F10+F8 -> 35931.007 | G11: =G10+G8 -> 28983.153 | H11: =H10+H8 -> 21957.816 | I11: =I10+I8 -> 13911.379 | J11: =J10+J8 -> 1648.6429 | ... AL11: =AL10+AL8 -> 1089418.9
A12: Cumulative Position | B12: CHF | C12: =C11 -> 72576.319 | D12: =D11 -> 58046.219 | E12: =E11 -> 43529.53 | F12: =F11 -> 35931.007 | G12: =G11 -> 28983.153 | H12: =H11 -> 21957.816 | I12: =I11 -> 13911.379 | J12: =J11 -> 1648.6429 | ... AL12: =AL11 -> 1089418.9
A13: RUNWAY
